Traceback (most recent call last):
  File "/Users/dmunselt/Documents/AICodingAssess/iris_pipeline/work/43/f04b3759e2809a3f1e1da96c9639d0/slice_test.py", line 33, in <module>
    group1 = sys.argv[2]
             ~~~~~~~~^^^
IndexError: list index out of range
